2021/02/15 05:50:46 : products_errors 9: Traceback (most recent call last):
  File "/var/www/python/cartmigration/controllers/migration.py", line 1036, in migration
    convert = fn_convert_export(main, ext)
  File "/var/www/python/cartmigration/models/cart/custom.py", line 538, in convert_product_export
    product_description = get_row_from_list_by_field(products_ext_data['products_to_categories'], 'product_id', product['product_id'])
KeyError: 'product_id'

2021/02/15 05:54:40 : products_errors 10: Traceback (most recent call last):
  File "/var/www/python/cartmigration/controllers/migration.py", line 1036, in migration
    convert = fn_convert_export(main, ext)
  File "/var/www/python/cartmigration/models/cart/custom.py", line 538, in convert_product_export
    product_description = get_row_from_list_by_field(products_ext_data['products_to_categories'], 'product_id', product['product_id'])
KeyError: 'product_id'

