2021/02/16 10:43:48 : orders_errors 1: Traceback (most recent call last):
  File "/var/www/python/cartmigration/controllers/migration.py", line 1036, in migration
    convert = fn_convert_export(main, ext)
  File "/var/www/python/cartmigration/models/cart/custom.py", line 1203, in convert_order_export
    order_item['qty'] = order_product['quantity']
KeyError: 'quantity'

