2021/02/16 13:08:34 : products_errors 9: Traceback (most recent call last):
  File "/var/www/python/cartmigration/controllers/migration.py", line 1036, in migration
    convert = fn_convert_export(main, ext)
  File "/var/www/python/cartmigration/models/cart/custom.py", line 534, in convert_product_export
    product_data['length'] = product(product['products_length'])
TypeError: 'dict' object is not callable

2021/02/16 13:08:34 : products_errors 10: Traceback (most recent call last):
  File "/var/www/python/cartmigration/controllers/migration.py", line 1036, in migration
    convert = fn_convert_export(main, ext)
  File "/var/www/python/cartmigration/models/cart/custom.py", line 534, in convert_product_export
    product_data['length'] = product(product['products_length'])
TypeError: 'dict' object is not callable

2021/02/16 13:08:34 : products_errors 16: Traceback (most recent call last):
  File "/var/www/python/cartmigration/controllers/migration.py", line 1036, in migration
    convert = fn_convert_export(main, ext)
  File "/var/www/python/cartmigration/models/cart/custom.py", line 534, in convert_product_export
    product_data['length'] = product(product['products_length'])
TypeError: 'dict' object is not callable

2021/02/16 13:08:34 : products_errors 17: Traceback (most recent call last):
  File "/var/www/python/cartmigration/controllers/migration.py", line 1036, in migration
    convert = fn_convert_export(main, ext)
  File "/var/www/python/cartmigration/models/cart/custom.py", line 534, in convert_product_export
    product_data['length'] = product(product['products_length'])
TypeError: 'dict' object is not callable

2021/02/16 13:08:35 : products_errors 18: Traceback (most recent call last):
  File "/var/www/python/cartmigration/controllers/migration.py", line 1036, in migration
    convert = fn_convert_export(main, ext)
  File "/var/www/python/cartmigration/models/cart/custom.py", line 534, in convert_product_export
    product_data['length'] = product(product['products_length'])
TypeError: 'dict' object is not callable

2021/02/16 13:08:35 : products_errors 19: Traceback (most recent call last):
  File "/var/www/python/cartmigration/controllers/migration.py", line 1036, in migration
    convert = fn_convert_export(main, ext)
  File "/var/www/python/cartmigration/models/cart/custom.py", line 534, in convert_product_export
    product_data['length'] = product(product['products_length'])
TypeError: 'dict' object is not callable

2021/02/16 13:08:35 : products_errors 20: Traceback (most recent call last):
  File "/var/www/python/cartmigration/controllers/migration.py", line 1036, in migration
    convert = fn_convert_export(main, ext)
  File "/var/www/python/cartmigration/models/cart/custom.py", line 534, in convert_product_export
    product_data['length'] = product(product['products_length'])
TypeError: 'dict' object is not callable

2021/02/16 13:08:35 : products_errors 22: Traceback (most recent call last):
  File "/var/www/python/cartmigration/controllers/migration.py", line 1036, in migration
    convert = fn_convert_export(main, ext)
  File "/var/www/python/cartmigration/models/cart/custom.py", line 534, in convert_product_export
    product_data['length'] = product(product['products_length'])
TypeError: 'dict' object is not callable

2021/02/16 13:08:35 : products_errors 23: Traceback (most recent call last):
  File "/var/www/python/cartmigration/controllers/migration.py", line 1036, in migration
    convert = fn_convert_export(main, ext)
  File "/var/www/python/cartmigration/models/cart/custom.py", line 534, in convert_product_export
    product_data['length'] = product(product['products_length'])
TypeError: 'dict' object is not callable

2021/02/16 13:08:35 : products_errors 24: Traceback (most recent call last):
  File "/var/www/python/cartmigration/controllers/migration.py", line 1036, in migration
    convert = fn_convert_export(main, ext)
  File "/var/www/python/cartmigration/models/cart/custom.py", line 534, in convert_product_export
    product_data['length'] = product(product['products_length'])
TypeError: 'dict' object is not callable

2021/02/16 13:08:35 : products_errors 25: Traceback (most recent call last):
  File "/var/www/python/cartmigration/controllers/migration.py", line 1036, in migration
    convert = fn_convert_export(main, ext)
  File "/var/www/python/cartmigration/models/cart/custom.py", line 534, in convert_product_export
    product_data['length'] = product(product['products_length'])
TypeError: 'dict' object is not callable

2021/02/16 13:08:35 : products_errors 37: Traceback (most recent call last):
  File "/var/www/python/cartmigration/controllers/migration.py", line 1036, in migration
    convert = fn_convert_export(main, ext)
  File "/var/www/python/cartmigration/models/cart/custom.py", line 534, in convert_product_export
    product_data['length'] = product(product['products_length'])
TypeError: 'dict' object is not callable

2021/02/16 13:08:35 : products_errors 39: Traceback (most recent call last):
  File "/var/www/python/cartmigration/controllers/migration.py", line 1036, in migration
    convert = fn_convert_export(main, ext)
  File "/var/www/python/cartmigration/models/cart/custom.py", line 534, in convert_product_export
    product_data['length'] = product(product['products_length'])
TypeError: 'dict' object is not callable

2021/02/16 13:08:35 : products_errors 41: Traceback (most recent call last):
  File "/var/www/python/cartmigration/controllers/migration.py", line 1036, in migration
    convert = fn_convert_export(main, ext)
  File "/var/www/python/cartmigration/models/cart/custom.py", line 534, in convert_product_export
    product_data['length'] = product(product['products_length'])
TypeError: 'dict' object is not callable

2021/02/16 13:08:35 : products_errors 42: Traceback (most recent call last):
  File "/var/www/python/cartmigration/controllers/migration.py", line 1036, in migration
    convert = fn_convert_export(main, ext)
  File "/var/www/python/cartmigration/models/cart/custom.py", line 534, in convert_product_export
    product_data['length'] = product(product['products_length'])
TypeError: 'dict' object is not callable

2021/02/16 13:08:35 : products_errors 43: Traceback (most recent call last):
  File "/var/www/python/cartmigration/controllers/migration.py", line 1036, in migration
    convert = fn_convert_export(main, ext)
  File "/var/www/python/cartmigration/models/cart/custom.py", line 534, in convert_product_export
    product_data['length'] = product(product['products_length'])
TypeError: 'dict' object is not callable

2021/02/16 13:08:35 : products_errors 44: Traceback (most recent call last):
  File "/var/www/python/cartmigration/controllers/migration.py", line 1036, in migration
    convert = fn_convert_export(main, ext)
  File "/var/www/python/cartmigration/models/cart/custom.py", line 534, in convert_product_export
    product_data['length'] = product(product['products_length'])
TypeError: 'dict' object is not callable

2021/02/16 13:08:35 : products_errors 47: Traceback (most recent call last):
  File "/var/www/python/cartmigration/controllers/migration.py", line 1036, in migration
    convert = fn_convert_export(main, ext)
  File "/var/www/python/cartmigration/models/cart/custom.py", line 534, in convert_product_export
    product_data['length'] = product(product['products_length'])
TypeError: 'dict' object is not callable

2021/02/16 13:08:35 : products_errors 48: Traceback (most recent call last):
  File "/var/www/python/cartmigration/controllers/migration.py", line 1036, in migration
    convert = fn_convert_export(main, ext)
  File "/var/www/python/cartmigration/models/cart/custom.py", line 534, in convert_product_export
    product_data['length'] = product(product['products_length'])
TypeError: 'dict' object is not callable

2021/02/16 13:08:35 : products_errors 49: Traceback (most recent call last):
  File "/var/www/python/cartmigration/controllers/migration.py", line 1036, in migration
    convert = fn_convert_export(main, ext)
  File "/var/www/python/cartmigration/models/cart/custom.py", line 534, in convert_product_export
    product_data['length'] = product(product['products_length'])
TypeError: 'dict' object is not callable

2021/02/16 13:08:39 : customer id 3 import failed. Error: email: contains an invalid domain name
2021/02/16 13:08:49 : order id 5 import failed. Error: Exceeded  API rate limit, please try again in a minute. Upgrade to a paid account to remove this limit.
2021/02/16 13:08:52 : order id 6 import failed. Error: Exceeded  API rate limit, please try again in a minute. Upgrade to a paid account to remove this limit.
2021/02/16 13:08:55 : order id 7 import failed. Error: Exceeded  API rate limit, please try again in a minute. Upgrade to a paid account to remove this limit.
2021/02/16 13:08:58 : order id 8 import failed. Error: Exceeded  API rate limit, please try again in a minute. Upgrade to a paid account to remove this limit.
