2021/02/14 19:40:22 : categories_errors 2: Traceback (most recent call last):
  File "/var/www/python/cartmigration/controllers/migration.py", line 1036, in migration
    convert = fn_convert_export(main, ext)
  File "/var/www/python/cartmigration/models/cart/custom.py", line 379, in convert_category_export
    category_data['id'] = category['id']
KeyError: 'id'

2021/02/14 19:40:22 : categories_errors 3: Traceback (most recent call last):
  File "/var/www/python/cartmigration/controllers/migration.py", line 1036, in migration
    convert = fn_convert_export(main, ext)
  File "/var/www/python/cartmigration/models/cart/custom.py", line 379, in convert_category_export
    category_data['id'] = category['id']
KeyError: 'id'

2021/02/14 19:40:22 : categories_errors 4: Traceback (most recent call last):
  File "/var/www/python/cartmigration/controllers/migration.py", line 1036, in migration
    convert = fn_convert_export(main, ext)
  File "/var/www/python/cartmigration/models/cart/custom.py", line 379, in convert_category_export
    category_data['id'] = category['id']
KeyError: 'id'

2021/02/14 19:40:22 : categories_errors 5: Traceback (most recent call last):
  File "/var/www/python/cartmigration/controllers/migration.py", line 1036, in migration
    convert = fn_convert_export(main, ext)
  File "/var/www/python/cartmigration/models/cart/custom.py", line 379, in convert_category_export
    category_data['id'] = category['id']
KeyError: 'id'

2021/02/14 19:40:22 : categories_errors 6: Traceback (most recent call last):
  File "/var/www/python/cartmigration/controllers/migration.py", line 1036, in migration
    convert = fn_convert_export(main, ext)
  File "/var/www/python/cartmigration/models/cart/custom.py", line 379, in convert_category_export
    category_data['id'] = category['id']
KeyError: 'id'

2021/02/14 19:40:22 : categories_errors 7: Traceback (most recent call last):
  File "/var/www/python/cartmigration/controllers/migration.py", line 1036, in migration
    convert = fn_convert_export(main, ext)
  File "/var/www/python/cartmigration/models/cart/custom.py", line 379, in convert_category_export
    category_data['id'] = category['id']
KeyError: 'id'

2021/02/14 19:40:22 : categories_errors 8: Traceback (most recent call last):
  File "/var/www/python/cartmigration/controllers/migration.py", line 1036, in migration
    convert = fn_convert_export(main, ext)
  File "/var/www/python/cartmigration/models/cart/custom.py", line 379, in convert_category_export
    category_data['id'] = category['id']
KeyError: 'id'

2021/02/14 19:40:22 : categories_errors 9: Traceback (most recent call last):
  File "/var/www/python/cartmigration/controllers/migration.py", line 1036, in migration
    convert = fn_convert_export(main, ext)
  File "/var/www/python/cartmigration/models/cart/custom.py", line 379, in convert_category_export
    category_data['id'] = category['id']
KeyError: 'id'

2021/02/14 19:40:22 : categories_errors 10: Traceback (most recent call last):
  File "/var/www/python/cartmigration/controllers/migration.py", line 1036, in migration
    convert = fn_convert_export(main, ext)
  File "/var/www/python/cartmigration/models/cart/custom.py", line 379, in convert_category_export
    category_data['id'] = category['id']
KeyError: 'id'

2021/02/14 19:40:22 : categories_errors 11: Traceback (most recent call last):
  File "/var/www/python/cartmigration/controllers/migration.py", line 1036, in migration
    convert = fn_convert_export(main, ext)
  File "/var/www/python/cartmigration/models/cart/custom.py", line 379, in convert_category_export
    category_data['id'] = category['id']
KeyError: 'id'

2021/02/14 19:40:22 : categories_errors 12: Traceback (most recent call last):
  File "/var/www/python/cartmigration/controllers/migration.py", line 1036, in migration
    convert = fn_convert_export(main, ext)
  File "/var/www/python/cartmigration/models/cart/custom.py", line 379, in convert_category_export
    category_data['id'] = category['id']
KeyError: 'id'

2021/02/14 19:40:22 : categories_errors 13: Traceback (most recent call last):
  File "/var/www/python/cartmigration/controllers/migration.py", line 1036, in migration
    convert = fn_convert_export(main, ext)
  File "/var/www/python/cartmigration/models/cart/custom.py", line 379, in convert_category_export
    category_data['id'] = category['id']
KeyError: 'id'

2021/02/14 19:40:22 : categories_errors 14: Traceback (most recent call last):
  File "/var/www/python/cartmigration/controllers/migration.py", line 1036, in migration
    convert = fn_convert_export(main, ext)
  File "/var/www/python/cartmigration/models/cart/custom.py", line 379, in convert_category_export
    category_data['id'] = category['id']
KeyError: 'id'

2021/02/14 19:40:22 : categories_errors 15: Traceback (most recent call last):
  File "/var/www/python/cartmigration/controllers/migration.py", line 1036, in migration
    convert = fn_convert_export(main, ext)
  File "/var/www/python/cartmigration/models/cart/custom.py", line 379, in convert_category_export
    category_data['id'] = category['id']
KeyError: 'id'

2021/02/14 19:40:22 : categories_errors 16: Traceback (most recent call last):
  File "/var/www/python/cartmigration/controllers/migration.py", line 1036, in migration
    convert = fn_convert_export(main, ext)
  File "/var/www/python/cartmigration/models/cart/custom.py", line 379, in convert_category_export
    category_data['id'] = category['id']
KeyError: 'id'

2021/02/14 19:40:22 : categories_errors 17: Traceback (most recent call last):
  File "/var/www/python/cartmigration/controllers/migration.py", line 1036, in migration
    convert = fn_convert_export(main, ext)
  File "/var/www/python/cartmigration/models/cart/custom.py", line 379, in convert_category_export
    category_data['id'] = category['id']
KeyError: 'id'

2021/02/14 19:40:22 : categories_errors 19: Traceback (most recent call last):
  File "/var/www/python/cartmigration/controllers/migration.py", line 1036, in migration
    convert = fn_convert_export(main, ext)
  File "/var/www/python/cartmigration/models/cart/custom.py", line 379, in convert_category_export
    category_data['id'] = category['id']
KeyError: 'id'

2021/02/14 19:40:22 : categories_errors 20: Traceback (most recent call last):
  File "/var/www/python/cartmigration/controllers/migration.py", line 1036, in migration
    convert = fn_convert_export(main, ext)
  File "/var/www/python/cartmigration/models/cart/custom.py", line 379, in convert_category_export
    category_data['id'] = category['id']
KeyError: 'id'

2021/02/14 19:40:22 : categories_errors 22: Traceback (most recent call last):
  File "/var/www/python/cartmigration/controllers/migration.py", line 1036, in migration
    convert = fn_convert_export(main, ext)
  File "/var/www/python/cartmigration/models/cart/custom.py", line 379, in convert_category_export
    category_data['id'] = category['id']
KeyError: 'id'

2021/02/14 19:40:22 : categories_errors 23: Traceback (most recent call last):
  File "/var/www/python/cartmigration/controllers/migration.py", line 1036, in migration
    convert = fn_convert_export(main, ext)
  File "/var/www/python/cartmigration/models/cart/custom.py", line 379, in convert_category_export
    category_data['id'] = category['id']
KeyError: 'id'

2021/02/14 19:40:23 : products_errors 9: Traceback (most recent call last):
  File "/var/www/python/cartmigration/controllers/migration.py", line 1036, in migration
    convert = fn_convert_export(main, ext)
  File "/var/www/python/cartmigration/models/cart/custom.py", line 524, in convert_product_export
    product_data['id'] = product['id']
KeyError: 'id'

2021/02/14 19:40:23 : products_errors 10: Traceback (most recent call last):
  File "/var/www/python/cartmigration/controllers/migration.py", line 1036, in migration
    convert = fn_convert_export(main, ext)
  File "/var/www/python/cartmigration/models/cart/custom.py", line 524, in convert_product_export
    product_data['id'] = product['id']
KeyError: 'id'

2021/02/14 19:40:23 : products_errors 16: Traceback (most recent call last):
  File "/var/www/python/cartmigration/controllers/migration.py", line 1036, in migration
    convert = fn_convert_export(main, ext)
  File "/var/www/python/cartmigration/models/cart/custom.py", line 524, in convert_product_export
    product_data['id'] = product['id']
KeyError: 'id'

2021/02/14 19:40:23 : products_errors 17: Traceback (most recent call last):
  File "/var/www/python/cartmigration/controllers/migration.py", line 1036, in migration
    convert = fn_convert_export(main, ext)
  File "/var/www/python/cartmigration/models/cart/custom.py", line 524, in convert_product_export
    product_data['id'] = product['id']
KeyError: 'id'

2021/02/14 19:40:23 : products_errors 18: Traceback (most recent call last):
  File "/var/www/python/cartmigration/controllers/migration.py", line 1036, in migration
    convert = fn_convert_export(main, ext)
  File "/var/www/python/cartmigration/models/cart/custom.py", line 524, in convert_product_export
    product_data['id'] = product['id']
KeyError: 'id'

2021/02/14 19:40:23 : products_errors 19: Traceback (most recent call last):
  File "/var/www/python/cartmigration/controllers/migration.py", line 1036, in migration
    convert = fn_convert_export(main, ext)
  File "/var/www/python/cartmigration/models/cart/custom.py", line 524, in convert_product_export
    product_data['id'] = product['id']
KeyError: 'id'

2021/02/14 19:40:23 : products_errors 20: Traceback (most recent call last):
  File "/var/www/python/cartmigration/controllers/migration.py", line 1036, in migration
    convert = fn_convert_export(main, ext)
  File "/var/www/python/cartmigration/models/cart/custom.py", line 524, in convert_product_export
    product_data['id'] = product['id']
KeyError: 'id'

2021/02/14 19:40:23 : products_errors 22: Traceback (most recent call last):
  File "/var/www/python/cartmigration/controllers/migration.py", line 1036, in migration
    convert = fn_convert_export(main, ext)
  File "/var/www/python/cartmigration/models/cart/custom.py", line 524, in convert_product_export
    product_data['id'] = product['id']
KeyError: 'id'

2021/02/14 19:40:23 : products_errors 23: Traceback (most recent call last):
  File "/var/www/python/cartmigration/controllers/migration.py", line 1036, in migration
    convert = fn_convert_export(main, ext)
  File "/var/www/python/cartmigration/models/cart/custom.py", line 524, in convert_product_export
    product_data['id'] = product['id']
KeyError: 'id'

2021/02/14 19:40:23 : products_errors 24: Traceback (most recent call last):
  File "/var/www/python/cartmigration/controllers/migration.py", line 1036, in migration
    convert = fn_convert_export(main, ext)
  File "/var/www/python/cartmigration/models/cart/custom.py", line 524, in convert_product_export
    product_data['id'] = product['id']
KeyError: 'id'

2021/02/14 19:40:23 : products_errors 25: Traceback (most recent call last):
  File "/var/www/python/cartmigration/controllers/migration.py", line 1036, in migration
    convert = fn_convert_export(main, ext)
  File "/var/www/python/cartmigration/models/cart/custom.py", line 524, in convert_product_export
    product_data['id'] = product['id']
KeyError: 'id'

2021/02/14 19:40:23 : products_errors 37: Traceback (most recent call last):
  File "/var/www/python/cartmigration/controllers/migration.py", line 1036, in migration
    convert = fn_convert_export(main, ext)
  File "/var/www/python/cartmigration/models/cart/custom.py", line 524, in convert_product_export
    product_data['id'] = product['id']
KeyError: 'id'

2021/02/14 19:40:23 : products_errors 39: Traceback (most recent call last):
  File "/var/www/python/cartmigration/controllers/migration.py", line 1036, in migration
    convert = fn_convert_export(main, ext)
  File "/var/www/python/cartmigration/models/cart/custom.py", line 524, in convert_product_export
    product_data['id'] = product['id']
KeyError: 'id'

2021/02/14 19:40:23 : products_errors 41: Traceback (most recent call last):
  File "/var/www/python/cartmigration/controllers/migration.py", line 1036, in migration
    convert = fn_convert_export(main, ext)
  File "/var/www/python/cartmigration/models/cart/custom.py", line 524, in convert_product_export
    product_data['id'] = product['id']
KeyError: 'id'

2021/02/14 19:40:23 : products_errors 42: Traceback (most recent call last):
  File "/var/www/python/cartmigration/controllers/migration.py", line 1036, in migration
    convert = fn_convert_export(main, ext)
  File "/var/www/python/cartmigration/models/cart/custom.py", line 524, in convert_product_export
    product_data['id'] = product['id']
KeyError: 'id'

2021/02/14 19:40:23 : products_errors 43: Traceback (most recent call last):
  File "/var/www/python/cartmigration/controllers/migration.py", line 1036, in migration
    convert = fn_convert_export(main, ext)
  File "/var/www/python/cartmigration/models/cart/custom.py", line 524, in convert_product_export
    product_data['id'] = product['id']
KeyError: 'id'

2021/02/14 19:40:23 : products_errors 44: Traceback (most recent call last):
  File "/var/www/python/cartmigration/controllers/migration.py", line 1036, in migration
    convert = fn_convert_export(main, ext)
  File "/var/www/python/cartmigration/models/cart/custom.py", line 524, in convert_product_export
    product_data['id'] = product['id']
KeyError: 'id'

2021/02/14 19:40:23 : products_errors 47: Traceback (most recent call last):
  File "/var/www/python/cartmigration/controllers/migration.py", line 1036, in migration
    convert = fn_convert_export(main, ext)
  File "/var/www/python/cartmigration/models/cart/custom.py", line 524, in convert_product_export
    product_data['id'] = product['id']
KeyError: 'id'

2021/02/14 19:40:23 : products_errors 48: Traceback (most recent call last):
  File "/var/www/python/cartmigration/controllers/migration.py", line 1036, in migration
    convert = fn_convert_export(main, ext)
  File "/var/www/python/cartmigration/models/cart/custom.py", line 524, in convert_product_export
    product_data['id'] = product['id']
KeyError: 'id'

2021/02/14 19:40:23 : products_errors 49: Traceback (most recent call last):
  File "/var/www/python/cartmigration/controllers/migration.py", line 1036, in migration
    convert = fn_convert_export(main, ext)
  File "/var/www/python/cartmigration/models/cart/custom.py", line 524, in convert_product_export
    product_data['id'] = product['id']
KeyError: 'id'

2021/02/14 19:40:24 : customers_errors 1: Traceback (most recent call last):
  File "/var/www/python/cartmigration/controllers/migration.py", line 1036, in migration
    convert = fn_convert_export(main, ext)
  File "/var/www/python/cartmigration/models/cart/custom.py", line 906, in convert_customer_export
    customer_data['id'] = customer['id']
KeyError: 'id'

2021/02/14 19:40:24 : customers_errors 3: Traceback (most recent call last):
  File "/var/www/python/cartmigration/controllers/migration.py", line 1036, in migration
    convert = fn_convert_export(main, ext)
  File "/var/www/python/cartmigration/models/cart/custom.py", line 906, in convert_customer_export
    customer_data['id'] = customer['id']
KeyError: 'id'

