2021/02/15 11:45:31 : products_errors 9: Traceback (most recent call last):
  File "/var/www/python/cartmigration/controllers/migration.py", line 1072, in migration
    import_data = fn_import(convert_data, main, ext)
  File "/var/www/python/cartmigration/models/cart/shopify.py", line 1999, in product_import
    response = self.api('products.json', post_data, 'Post')
  File "/var/www/python/cartmigration/models/cart/shopify.py", line 3699, in api
    data = json.dumps(data)
  File "/usr/local/lib/python3.7/json/__init__.py", line 231, in dumps
    return _default_encoder.encode(obj)
  File "/usr/local/lib/python3.7/json/encoder.py", line 199, in encode
    chunks = self.iterencode(o, _one_shot=True)
  File "/usr/local/lib/python3.7/json/encoder.py", line 257, in iterencode
    return _iterencode(o, 0)
  File "/usr/local/lib/python3.7/json/encoder.py", line 179, in default
    raise TypeError(f'Object of type {o.__class__.__name__} '
TypeError: Object of type datetime is not JSON serializable

