2021/02/14 19:49:08 : categories_errors 2: Traceback (most recent call last):
  File "/var/www/python/cartmigration/controllers/migration.py", line 1036, in migration
    convert = fn_convert_export(main, ext)
  File "/var/www/python/cartmigration/models/cart/custom.py", line 380, in convert_category_export
    category_data['id'] = category['id']
KeyError: 'id'

2021/02/14 19:49:08 : categories_errors 3: Traceback (most recent call last):
  File "/var/www/python/cartmigration/controllers/migration.py", line 1036, in migration
    convert = fn_convert_export(main, ext)
  File "/var/www/python/cartmigration/models/cart/custom.py", line 380, in convert_category_export
    category_data['id'] = category['id']
KeyError: 'id'

2021/02/14 19:49:08 : categories_errors 4: Traceback (most recent call last):
  File "/var/www/python/cartmigration/controllers/migration.py", line 1036, in migration
    convert = fn_convert_export(main, ext)
  File "/var/www/python/cartmigration/models/cart/custom.py", line 380, in convert_category_export
    category_data['id'] = category['id']
KeyError: 'id'

2021/02/14 19:49:08 : categories_errors 5: Traceback (most recent call last):
  File "/var/www/python/cartmigration/controllers/migration.py", line 1036, in migration
    convert = fn_convert_export(main, ext)
  File "/var/www/python/cartmigration/models/cart/custom.py", line 380, in convert_category_export
    category_data['id'] = category['id']
KeyError: 'id'

2021/02/14 19:49:08 : categories_errors 6: Traceback (most recent call last):
  File "/var/www/python/cartmigration/controllers/migration.py", line 1036, in migration
    convert = fn_convert_export(main, ext)
  File "/var/www/python/cartmigration/models/cart/custom.py", line 380, in convert_category_export
    category_data['id'] = category['id']
KeyError: 'id'

2021/02/14 19:49:08 : categories_errors 7: Traceback (most recent call last):
  File "/var/www/python/cartmigration/controllers/migration.py", line 1036, in migration
    convert = fn_convert_export(main, ext)
  File "/var/www/python/cartmigration/models/cart/custom.py", line 380, in convert_category_export
    category_data['id'] = category['id']
KeyError: 'id'

2021/02/14 19:49:08 : categories_errors 8: Traceback (most recent call last):
  File "/var/www/python/cartmigration/controllers/migration.py", line 1036, in migration
    convert = fn_convert_export(main, ext)
  File "/var/www/python/cartmigration/models/cart/custom.py", line 380, in convert_category_export
    category_data['id'] = category['id']
KeyError: 'id'

2021/02/14 19:49:08 : categories_errors 9: Traceback (most recent call last):
  File "/var/www/python/cartmigration/controllers/migration.py", line 1036, in migration
    convert = fn_convert_export(main, ext)
  File "/var/www/python/cartmigration/models/cart/custom.py", line 380, in convert_category_export
    category_data['id'] = category['id']
KeyError: 'id'

2021/02/14 19:49:09 : categories_errors 10: Traceback (most recent call last):
  File "/var/www/python/cartmigration/controllers/migration.py", line 1036, in migration
    convert = fn_convert_export(main, ext)
  File "/var/www/python/cartmigration/models/cart/custom.py", line 380, in convert_category_export
    category_data['id'] = category['id']
KeyError: 'id'

2021/02/14 19:49:09 : categories_errors 11: Traceback (most recent call last):
  File "/var/www/python/cartmigration/controllers/migration.py", line 1036, in migration
    convert = fn_convert_export(main, ext)
  File "/var/www/python/cartmigration/models/cart/custom.py", line 380, in convert_category_export
    category_data['id'] = category['id']
KeyError: 'id'

2021/02/14 19:49:09 : categories_errors 12: Traceback (most recent call last):
  File "/var/www/python/cartmigration/controllers/migration.py", line 1036, in migration
    convert = fn_convert_export(main, ext)
  File "/var/www/python/cartmigration/models/cart/custom.py", line 380, in convert_category_export
    category_data['id'] = category['id']
KeyError: 'id'

2021/02/14 19:49:09 : categories_errors 13: Traceback (most recent call last):
  File "/var/www/python/cartmigration/controllers/migration.py", line 1036, in migration
    convert = fn_convert_export(main, ext)
  File "/var/www/python/cartmigration/models/cart/custom.py", line 380, in convert_category_export
    category_data['id'] = category['id']
KeyError: 'id'

2021/02/14 19:49:09 : categories_errors 14: Traceback (most recent call last):
  File "/var/www/python/cartmigration/controllers/migration.py", line 1036, in migration
    convert = fn_convert_export(main, ext)
  File "/var/www/python/cartmigration/models/cart/custom.py", line 380, in convert_category_export
    category_data['id'] = category['id']
KeyError: 'id'

2021/02/14 19:49:09 : categories_errors 15: Traceback (most recent call last):
  File "/var/www/python/cartmigration/controllers/migration.py", line 1036, in migration
    convert = fn_convert_export(main, ext)
  File "/var/www/python/cartmigration/models/cart/custom.py", line 380, in convert_category_export
    category_data['id'] = category['id']
KeyError: 'id'

2021/02/14 19:49:09 : categories_errors 16: Traceback (most recent call last):
  File "/var/www/python/cartmigration/controllers/migration.py", line 1036, in migration
    convert = fn_convert_export(main, ext)
  File "/var/www/python/cartmigration/models/cart/custom.py", line 380, in convert_category_export
    category_data['id'] = category['id']
KeyError: 'id'

2021/02/14 19:49:09 : categories_errors 17: Traceback (most recent call last):
  File "/var/www/python/cartmigration/controllers/migration.py", line 1036, in migration
    convert = fn_convert_export(main, ext)
  File "/var/www/python/cartmigration/models/cart/custom.py", line 380, in convert_category_export
    category_data['id'] = category['id']
KeyError: 'id'

2021/02/14 19:49:09 : categories_errors 19: Traceback (most recent call last):
  File "/var/www/python/cartmigration/controllers/migration.py", line 1036, in migration
    convert = fn_convert_export(main, ext)
  File "/var/www/python/cartmigration/models/cart/custom.py", line 380, in convert_category_export
    category_data['id'] = category['id']
KeyError: 'id'

2021/02/14 19:49:09 : categories_errors 20: Traceback (most recent call last):
  File "/var/www/python/cartmigration/controllers/migration.py", line 1036, in migration
    convert = fn_convert_export(main, ext)
  File "/var/www/python/cartmigration/models/cart/custom.py", line 380, in convert_category_export
    category_data['id'] = category['id']
KeyError: 'id'

2021/02/14 19:49:09 : categories_errors 22: Traceback (most recent call last):
  File "/var/www/python/cartmigration/controllers/migration.py", line 1036, in migration
    convert = fn_convert_export(main, ext)
  File "/var/www/python/cartmigration/models/cart/custom.py", line 380, in convert_category_export
    category_data['id'] = category['id']
KeyError: 'id'

2021/02/14 19:49:09 : categories_errors 23: Traceback (most recent call last):
  File "/var/www/python/cartmigration/controllers/migration.py", line 1036, in migration
    convert = fn_convert_export(main, ext)
  File "/var/www/python/cartmigration/models/cart/custom.py", line 380, in convert_category_export
    category_data['id'] = category['id']
KeyError: 'id'

