2021/02/22 03:49:30 : customers_errors 1: Traceback (most recent call last):
  File "/var/www/python/cartmigration/controllers/migration.py", line 1036, in migration
    convert = fn_convert_export(main, ext)
  File "/var/www/python/cartmigration/models/cart/custom.py", line 1034, in convert_customer_export
    state = get_row_from_list_by_field(customers_ext['data']['zones'], 'zone_code', state_id)
KeyError: 'zones'

2021/02/22 03:49:30 : customers_errors 3: Traceback (most recent call last):
  File "/var/www/python/cartmigration/controllers/migration.py", line 1036, in migration
    convert = fn_convert_export(main, ext)
  File "/var/www/python/cartmigration/models/cart/custom.py", line 1034, in convert_customer_export
    state = get_row_from_list_by_field(customers_ext['data']['zones'], 'zone_code', state_id)
KeyError: 'zones'

